Traceback (most recent call last):
  File "/Users/scoutmckee/miniconda3/envs/datexplore_env/lib/python3.10/site-packages/jupyter_cache/executors/utils.py", line 58, in single_nb_execution
    executenb(
  File "/Users/scoutmckee/miniconda3/envs/datexplore_env/lib/python3.10/site-packages/nbclient/client.py", line 1314, in execute
    return NotebookClient(nb=nb, resources=resources, km=km, **kwargs).execute()
  File "/Users/scoutmckee/miniconda3/envs/datexplore_env/lib/python3.10/site-packages/jupyter_core/utils/__init__.py", line 165, in wrapped
    return loop.run_until_complete(inner)
  File "/Users/scoutmckee/miniconda3/envs/datexplore_env/lib/python3.10/asyncio/base_events.py", line 649, in run_until_complete
    return future.result()
  File "/Users/scoutmckee/miniconda3/envs/datexplore_env/lib/python3.10/site-packages/nbclient/client.py", line 709, in async_execute
    await self.async_execute_cell(
  File "/Users/scoutmckee/miniconda3/envs/datexplore_env/lib/python3.10/site-packages/nbclient/client.py", line 1062, in async_execute_cell
    await self._check_raise_for_error(cell, cell_index, exec_reply)
  File "/Users/scoutmckee/miniconda3/envs/datexplore_env/lib/python3.10/site-packages/nbclient/client.py", line 918, in _check_raise_for_error
    raise CellExecutionError.from_cell_and_msg(cell, exec_reply_content)
nbclient.exceptions.CellExecutionError: An error occurred while executing the following cell:
------------------
raw_df = pd.DataFrame({'Even Numbers': [2, 4, 6, 8],'odd numbers': [1, 3, 5, 7]})
filtered_df = raw_df.query("Even Numbers > 2")
------------------


Traceback [0;36m(most recent call last)[0m:

[0m  File [1;32m~/miniconda3/envs/datexplore_env/lib/python3.10/site-packages/IPython/core/interactiveshell.py:3553[0m in [1;35mrun_code[0m
    exec(code_obj, self.user_global_ns, self.user_ns)[0m

[0m  Cell [1;32mIn[2], line 2[0m
    filtered_df = raw_df.query("Even Numbers > 2")[0m

[0m  File [1;32m~/miniconda3/envs/datexplore_env/lib/python3.10/site-packages/pandas/core/frame.py:4599[0m in [1;35mquery[0m
    res = self.eval(expr, **kwargs)[0m

[0m  File [1;32m~/miniconda3/envs/datexplore_env/lib/python3.10/site-packages/pandas/core/frame.py:4725[0m in [1;35meval[0m
    return _eval(expr, inplace=inplace, **kwargs)[0m

[0m  File [1;32m~/miniconda3/envs/datexplore_env/lib/python3.10/site-packages/pandas/core/computation/eval.py:336[0m in [1;35meval[0m
    parsed_expr = Expr(expr, engine=engine, parser=parser, env=env)[0m

[0m  File [1;32m~/miniconda3/envs/datexplore_env/lib/python3.10/site-packages/pandas/core/computation/expr.py:808[0m in [1;35m__init__[0m
    self.terms = self.parse()[0m

[0m  File [1;32m~/miniconda3/envs/datexplore_env/lib/python3.10/site-packages/pandas/core/computation/expr.py:827[0m in [1;35mparse[0m
    return self._visitor.visit(self.expr)[0m

[0m  File [1;32m~/miniconda3/envs/datexplore_env/lib/python3.10/site-packages/pandas/core/computation/expr.py:407[0m in [1;35mvisit[0m
    raise e[0m

[0m  File [1;32m~/miniconda3/envs/datexplore_env/lib/python3.10/site-packages/pandas/core/computation/expr.py:403[0m in [1;35mvisit[0m
    node = ast.fix_missing_locations(ast.parse(clean))[0m

[0;36m  File [0;32m~/miniconda3/envs/datexplore_env/lib/python3.10/ast.py:50[0;36m in [0;35mparse[0;36m
[0;31m    return compile(source, filename, mode, flags,[0;36m

[0;36m  File [0;32m<unknown>:1[0;36m[0m
[0;31m    Even Numbers >2[0m
[0m         ^[0m
[0;31mSyntaxError[0m[0;31m:[0m invalid syntax


